<?xml version="1.0"?>
<robot xmlns:xacro="http://www.ros.org/wiki/xacro">

  <xacro:macro name="myrobot_description" params="parent">

  <!-- helper macro -->
    <xacro:macro name="create_link" params="
        link_name
        xyz_offset
        rpy_offset
        box_size
        ">
    <link name="${link_name}">
      <visual>
        <origin xyz="${xyz_offset}" rpy="${rpy_offset}"/>
        <geometry>
          <box size="${box_size}"/>
        </geometry>
      </visual>
      <collision>
        <origin xyz="${xyz_offset}" rpy="${rpy_offset}"/>
        <geometry>
          <box size="${box_size}"/>
        </geometry>
      </collision>
      <inertial>
        <mass value="1"/>
        <inertia ixx="1.0" ixy="0.0" ixz="0.0" iyy="1.0" iyz="0.0" izz="1.0"/>
      </inertial>
    </link>
  </xacro:macro>

  <!-- link definitions -->
  <xacro:create_link link_name="base_link" xyz_offset="0 0 0" rpy_offset="0 0 0" box_size="0.2 0.2 0.2"/>
  <xacro:create_link link_name="link1"     xyz_offset="0 0 0.075" rpy_offset="0 0 0" box_size="0.15 0.15 0.05"/>
  <xacro:create_link link_name="link2"     xyz_offset="0.15 0 0" rpy_offset="0 0 0" box_size="0.3 0.1 0.1"/>
  <xacro:create_link link_name="link3"     xyz_offset="0.25 0 0" rpy_offset="0 0 0" box_size="0.5 0.1 0.1"/>
  <xacro:create_link link_name="link4"     xyz_offset="0.2 0 0" rpy_offset="0 0 0" box_size="0.4 0.1 0.1"/>
  <xacro:create_link link_name="link5"     xyz_offset="0.1 0 0" rpy_offset="0 0 0" box_size="0.2 0.1 0.1"/>
  <xacro:create_link link_name="link6"     xyz_offset="0.075 0 0" rpy_offset="0 0 0" box_size="0.15 0.1 0.1"/>

  <link name="tool"/>

  <!-- joints - main serial chain -->
  <joint name="joint1" type="revolute">
    <parent link="base_link"/>
    <child link="link1"/>
    <origin xyz="0 0 0.061584" rpy="0 0 0"/>
    <axis xyz="0 0 1"/>
    <limit effort="1000.0" lower="${-pi}" upper="${pi}" velocity="2.5"/>
  </joint>

  <joint name="joint2" type="revolute">
    <parent link="link1"/>
    <child link="link2"/>
    <origin xyz="-0.101717 0 0.182284" rpy="${-pi/2} -${pi/3} ${pi/2}"/>
    <axis xyz="0 0 1"/>
    <limit effort="1000.0" lower="${-pi}" upper="${pi}" velocity="2.5"/>
  </joint>

  <joint name="joint3" type="revolute">
    <parent link="link2"/>
    <child link="link3"/>
    <origin xyz="0.685682 0 0.041861" rpy="0 ${pi} ${pi+pi/2}"/>
    <axis xyz="0 0 1"/>
    <limit effort="1000.0" lower="${-pi}" upper="${pi}" velocity="2.5"/>
  </joint>

  <joint name="joint4" type="revolute">
    <parent link="link3"/>
    <child link="link4"/>
    <origin xyz="0.518777 0 0.067458" rpy="0 ${pi} ${pi+pi/6}"/>
    <axis xyz="0 0 1"/>
    <limit effort="1000.0" lower="${-pi}" upper="${pi}" velocity="2.5"/>
  </joint>

  <joint name="joint5" type="revolute">
    <parent link="link4"/>
    <child link="link5"/>
    <origin xyz="0.112654 0 0.110903" rpy="${pi/2} ${pi} ${pi/2}"/>
    <axis xyz="0 0 1"/>
    <limit effort="1000.0" lower="${-pi}" upper="${pi}" velocity="2.5"/>
  </joint>

  <joint name="joint6" type="revolute">
    <parent link="link5"/>
    <child link="link6"/>
    <origin xyz="-0.085976 0 0.133436" rpy="0 ${-pi/2} 0"/>
    <axis xyz="0 0 1"/>
    <limit effort="1000.0" lower="${-pi}" upper="${pi}" velocity="2.5"/>
  </joint>
  
  <joint name="joint-tool" type="fixed">
    <parent link="link6"/>
    <child link="tool"/>
    <origin xyz="0 0 .185" rpy="0 0 0"/>
  </joint>

</xacro:macro>

</robot>