<?xml version="1.0"?>
<robot xmlns:xacro="http://www.ros.org/wiki/xacro">

  <xacro:macro name="myrobot_description" params="parent">


  <link name="base_link">
    <visual>
      <geometry>
        <box size="0.1 0.1 0.1"/>
      </geometry>
      <material name = "">
        <color rgba="0.8 0.8 0.8 1.0"/>
      </material>
    </visual>
    <collision>
      <geometry>
        <box size="0.1 0.1 0.1"/>
      </geometry>
    </collision>
  </link>

  <link name="link1">
    <visual>
      <geometry>
        <box size="0.2 0.1 0.1"/>
      </geometry>
      <material name = "">
        <color rgba="0.8 0.8 0.8 1.0"/>
      </material>
    </visual>
    <collision>
      <geometry>
        <box size="0.2 0.1 0.1"/>
      </geometry>
    </collision>
  </link>

  <link name="link2">
    <visual>
      <geometry>
        <box size="0.2 0.1 0.1"/>
      </geometry>
      <material name = "">
        <color rgba="0.8 0.8 0.8 1.0"/>
      </material>
    </visual>
    <collision>
      <geometry>
        <box size="0.2 0.1 0.1"/>
      </geometry>
    </collision>
  </link>

  <link name="link3">
    <visual>
      <geometry>
        <box size="0.2 0.1 0.1"/>
      </geometry>
      <material name = "">
        <color rgba="0.8 0.8 0.8 1.0"/>
      </material>
    </visual>
    <collision>
      <geometry>
        <box size="0.2 0.1 0.1"/>
      </geometry>
    </collision>
  </link>

  <link name="link4">
    <visual>
      <geometry>
        <box size="0.2 0.1 0.1"/>
      </geometry>
      <material name = "">
        <color rgba="0.8 0.8 0.8 1.0"/>
      </material>
    </visual>
    <collision>
      <geometry>
        <box size="0.2 0.1 0.1"/>
      </geometry>
    </collision>
  </link>

  <link name="link5">
    <visual>
      <geometry>
        <box size="0.2 0.1 0.1"/>
      </geometry>
      <material name = "">
        <color rgba="0.8 0.8 0.8 1.0"/>
      </material>
    </visual>
    <collision>
      <geometry>
        <box size="0.2 0.1 0.1"/>
      </geometry>
    </collision>
  </link>

  <link name="link6">
    <visual>
      <geometry>
        <box size="0.1 0.1 0.1"/>
      </geometry>
      <material name = "">
        <color rgba="0.8 0.8 0.8 1.0"/>
      </material>
    </visual>
    <collision>
      <geometry>
        <box size="0.1 0.1 0.1"/>
      </geometry>
    </collision>
  </link>

  <joint name="joint1" type="revolute">
    <origin xyz="0.0 0.0 0.1"/>
    <axis xyz="0 0 1"/>
    <parent link="${parent}"/>
    <child link="link1"/>
    <limit lower="-3.14159" upper="3.14159" effort="100" velocity="1.0"/>
  </joint>

  <joint name="joint2" type="revolute">
    <origin xyz="0.2 0.0 0.0"/>
    <axis xyz="0 0 1"/>
    <parent link="link1"/>
    <child link="link2"/>
    <limit lower="-3.14159" upper="3.14159" effort="100" velocity="1.0"/>
  </joint>

  <joint name="joint3" type="revolute">
    <origin xyz="0.2 0.0 0.0"/>
    <axis xyz="0 0 1"/>
    <parent link="link2"/>
    <child link="link3"/>
    <limit lower="-3.14159" upper="3.14159" effort="100" velocity="1.0"/>
  </joint>

  <joint name="joint4" type="revolute">
    <origin xyz="0.2 0.0 0.0"/>
    <axis xyz="0 0 1"/>
    <parent link="link3"/>
    <child link="link4"/>
    <limit lower="-3.14159" upper="3.14159" effort="100" velocity="1.0"/>
  </joint>

  <joint name="joint5" type="revolute">
    <origin xyz="0.2 0.0 0.0"/>
    <axis xyz="0 0 1"/>
    <parent link="link4"/>
    <child link="link5"/>
    <limit lower="-3.14159" upper="3.14159" effort="100" velocity="1.0"/>
  </joint>

  <joint name="joint6" type="revolute">
    <origin xyz="0.2 0.0 0.0"/>
    <axis xyz="0 0 1"/>
    <parent link="link5"/>
    <child link="link6"/>
    <limit lower="-3.14159" upper="3.14159" effort="100" velocity="1.0"/>
  </joint>

  </xacro:macro>

</robot>