<?xml version="1.0" ?>
<!-- =================================================================================== -->
<!-- |    This document was autogenerated by xacro from unibot.xacro                   | -->
<!-- |    EDITING THIS FILE BY HAND IS NOT RECOMMENDED                                 | -->
<!-- =================================================================================== -->
<robot name="unibot">
  <!-- Tail Link -->
  <link name="a1_tail">
    <inertial>
      <origin rpy="0.0 0.0 0.0" xyz="0.0 0.0 0.25"/>
      <mass value="1.0"/>
      <inertia ixx="1.0" ixy="0.0" ixz="0.0" iyy="1.0" iyz="0.0" izz="1.0"/>
    </inertial>
    <visual>
      <origin rpy="0.0 0.0 0.0" xyz="0.0 0.0 0.25"/>
      <geometry>
        <cylinder length="0.5" radius="0.1"/>
      </geometry>
      <material name="White">
        <color rgba="1.0 1.0 1.0 1.0"/>
      </material>
    </visual>
    <collision>
      <origin rpy="0.0 0.0 0.0" xyz="0.0 0.0 0.25"/>
      <geometry>
        <cylinder length="0.5" radius="0.1"/>
      </geometry>
    </collision>
  </link>
  <gazebo reference="a1_tail">
    <selfCollide>true</selfCollide>
    <material>Gazebo/White</material>
  </gazebo>
  <!-- Head Link -->
  <link name="a1_head">
    <inertial>
      <origin rpy="0.0 0.0 0.0" xyz="0.0 0.0 0.0"/>
      <mass value="1.0"/>
      <inertia ixx="1.0" ixy="0.0" ixz="0.0" iyy="1.0" iyz="0.0" izz="1.0"/>
    </inertial>
    <visual>
      <origin rpy="0.0 0.0 0.0" xyz="0.0 0.0 0.1"/>
      <geometry>
        <box size="0.2 0.2 0.2"/>
      </geometry>
      <material name="Blue">
        <color rgba="0.0 0.0 1.0 1.0"/>
      </material>
    </visual>
    <collision>
      <origin rpy="0.0 0.0 0.0" xyz="0.0 0.0 0.1"/>
      <geometry>
        <box size="0.2 0.2 0.2"/>
      </geometry>
    </collision>
  </link>
  <gazebo reference="a1_head">
    <selfCollide>true</selfCollide>
    <material>Gazebo/Blue</material>
  </gazebo>
  <!-- Joint -->
  <joint name="a1_joint" type="revolute">
    <origin rpy="0.0 0.0 0.0" xyz="0.0 0.0 0.5"/>
    <parent link="a1_tail"/>
    <child link="a1_head"/>
    <axis xyz="0.0 0.0 1.0"/>
    <limit effort="1000000" lower="-1.5707963267948966" upper="1.5707963267948966" velocity="1000000"/>
  </joint>
  <!-- Tail Link -->
  <link name="a2_tail">
    <inertial>
      <origin rpy="0.0 0.0 0.0" xyz="0.0 0.0 0.25"/>
      <mass value="1.0"/>
      <inertia ixx="1.0" ixy="0.0" ixz="0.0" iyy="1.0" iyz="0.0" izz="1.0"/>
    </inertial>
    <visual>
      <origin rpy="0.0 0.0 0.0" xyz="0.0 0.0 0.25"/>
      <geometry>
        <cylinder length="0.5" radius="0.1"/>
      </geometry>
      <material name="White">
        <color rgba="1.0 1.0 1.0 1.0"/>
      </material>
    </visual>
    <collision>
      <origin rpy="0.0 0.0 0.0" xyz="0.0 0.0 0.25"/>
      <geometry>
        <cylinder length="0.5" radius="0.1"/>
      </geometry>
    </collision>
  </link>
  <gazebo reference="a2_tail">
    <selfCollide>true</selfCollide>
    <material>Gazebo/White</material>
  </gazebo>
  <!-- Head Link -->
  <link name="a2_head">
    <inertial>
      <origin rpy="0.0 0.0 0.0" xyz="0.0 0.0 0.0"/>
      <mass value="1.0"/>
      <inertia ixx="1.0" ixy="0.0" ixz="0.0" iyy="1.0" iyz="0.0" izz="1.0"/>
    </inertial>
    <visual>
      <origin rpy="0.0 0.0 0.0" xyz="0.0 0.0 0.1"/>
      <geometry>
        <box size="0.2 0.2 0.2"/>
      </geometry>
      <material name="Blue">
        <color rgba="0.0 0.0 1.0 1.0"/>
      </material>
    </visual>
    <collision>
      <origin rpy="0.0 0.0 0.0" xyz="0.0 0.0 0.1"/>
      <geometry>
        <box size="0.2 0.2 0.2"/>
      </geometry>
    </collision>
  </link>
  <gazebo reference="a2_head">
    <selfCollide>true</selfCollide>
    <material>Gazebo/Blue</material>
  </gazebo>
  <!-- Joint -->
  <joint name="a2_joint" type="revolute">
    <origin rpy="0.0 0.0 0.0" xyz="0.0 0.0 0.5"/>
    <parent link="a2_tail"/>
    <child link="a2_head"/>
    <axis xyz="0.0 0.0 1.0"/>
    <limit effort="1000000" lower="-1.5707963267948966" upper="1.5707963267948966" velocity="1000000"/>
  </joint>
  <!-- Tail Link -->
  <link name="a3_tail">
    <inertial>
      <origin rpy="0.0 0.0 0.0" xyz="0.0 0.0 0.25"/>
      <mass value="1.0"/>
      <inertia ixx="1.0" ixy="0.0" ixz="0.0" iyy="1.0" iyz="0.0" izz="1.0"/>
    </inertial>
    <visual>
      <origin rpy="0.0 0.0 0.0" xyz="0.0 0.0 0.25"/>
      <geometry>
        <cylinder length="0.5" radius="0.1"/>
      </geometry>
      <material name="White">
        <color rgba="1.0 1.0 1.0 1.0"/>
      </material>
    </visual>
    <collision>
      <origin rpy="0.0 0.0 0.0" xyz="0.0 0.0 0.25"/>
      <geometry>
        <cylinder length="0.5" radius="0.1"/>
      </geometry>
    </collision>
  </link>
  <gazebo reference="a3_tail">
    <selfCollide>true</selfCollide>
    <material>Gazebo/White</material>
  </gazebo>
  <!-- Head Link -->
  <link name="a3_head">
    <inertial>
      <origin rpy="0.0 0.0 0.0" xyz="0.0 0.0 0.0"/>
      <mass value="1.0"/>
      <inertia ixx="1.0" ixy="0.0" ixz="0.0" iyy="1.0" iyz="0.0" izz="1.0"/>
    </inertial>
    <visual>
      <origin rpy="0.0 0.0 0.0" xyz="0.0 0.0 0.1"/>
      <geometry>
        <box size="0.2 0.2 0.2"/>
      </geometry>
      <material name="Blue">
        <color rgba="0.0 0.0 1.0 1.0"/>
      </material>
    </visual>
    <collision>
      <origin rpy="0.0 0.0 0.0" xyz="0.0 0.0 0.1"/>
      <geometry>
        <box size="0.2 0.2 0.2"/>
      </geometry>
    </collision>
  </link>
  <gazebo reference="a3_head">
    <selfCollide>true</selfCollide>
    <material>Gazebo/Blue</material>
  </gazebo>
  <!-- Joint -->
  <joint name="a3_joint" type="revolute">
    <origin rpy="0.0 0.0 0.0" xyz="0.0 0.0 0.5"/>
    <parent link="a3_tail"/>
    <child link="a3_head"/>
    <axis xyz="0.0 0.0 1.0"/>
    <limit effort="1000000" lower="-1.5707963267948966" upper="1.5707963267948966" velocity="1000000"/>
  </joint>
  <!-- Tail Link -->
  <link name="a4_tail">
    <inertial>
      <origin rpy="0.0 0.0 0.0" xyz="0.0 0.0 0.25"/>
      <mass value="1.0"/>
      <inertia ixx="1.0" ixy="0.0" ixz="0.0" iyy="1.0" iyz="0.0" izz="1.0"/>
    </inertial>
    <visual>
      <origin rpy="0.0 0.0 0.0" xyz="0.0 0.0 0.25"/>
      <geometry>
        <cylinder length="0.5" radius="0.1"/>
      </geometry>
      <material name="White">
        <color rgba="1.0 1.0 1.0 1.0"/>
      </material>
    </visual>
    <collision>
      <origin rpy="0.0 0.0 0.0" xyz="0.0 0.0 0.25"/>
      <geometry>
        <cylinder length="0.5" radius="0.1"/>
      </geometry>
    </collision>
  </link>
  <gazebo reference="a4_tail">
    <selfCollide>true</selfCollide>
    <material>Gazebo/White</material>
  </gazebo>
  <!-- Head Link -->
  <link name="a4_head">
    <inertial>
      <origin rpy="0.0 0.0 0.0" xyz="0.0 0.0 0.0"/>
      <mass value="1.0"/>
      <inertia ixx="1.0" ixy="0.0" ixz="0.0" iyy="1.0" iyz="0.0" izz="1.0"/>
    </inertial>
    <visual>
      <origin rpy="0.0 0.0 0.0" xyz="0.0 0.0 0.1"/>
      <geometry>
        <box size="0.2 0.2 0.2"/>
      </geometry>
      <material name="Blue">
        <color rgba="0.0 0.0 1.0 1.0"/>
      </material>
    </visual>
    <collision>
      <origin rpy="0.0 0.0 0.0" xyz="0.0 0.0 0.1"/>
      <geometry>
        <box size="0.2 0.2 0.2"/>
      </geometry>
    </collision>
  </link>
  <gazebo reference="a4_head">
    <selfCollide>true</selfCollide>
    <material>Gazebo/Blue</material>
  </gazebo>
  <!-- Joint -->
  <joint name="a4_joint" type="revolute">
    <origin rpy="0.0 0.0 0.0" xyz="0.0 0.0 0.5"/>
    <parent link="a4_tail"/>
    <child link="a4_head"/>
    <axis xyz="0.0 0.0 1.0"/>
    <limit effort="1000000" lower="-1.5707963267948966" upper="1.5707963267948966" velocity="1000000"/>
  </joint>
  <!-- Tail Link -->
  <link name="a5_tail">
    <inertial>
      <origin rpy="0.0 0.0 0.0" xyz="0.0 0.0 0.25"/>
      <mass value="1.0"/>
      <inertia ixx="1.0" ixy="0.0" ixz="0.0" iyy="1.0" iyz="0.0" izz="1.0"/>
    </inertial>
    <visual>
      <origin rpy="0.0 0.0 0.0" xyz="0.0 0.0 0.25"/>
      <geometry>
        <cylinder length="0.5" radius="0.1"/>
      </geometry>
      <material name="White">
        <color rgba="1.0 1.0 1.0 1.0"/>
      </material>
    </visual>
    <collision>
      <origin rpy="0.0 0.0 0.0" xyz="0.0 0.0 0.25"/>
      <geometry>
        <cylinder length="0.5" radius="0.1"/>
      </geometry>
    </collision>
  </link>
  <gazebo reference="a5_tail">
    <selfCollide>true</selfCollide>
    <material>Gazebo/White</material>
  </gazebo>
  <!-- Head Link -->
  <link name="a5_head">
    <inertial>
      <origin rpy="0.0 0.0 0.0" xyz="0.0 0.0 0.0"/>
      <mass value="1.0"/>
      <inertia ixx="1.0" ixy="0.0" ixz="0.0" iyy="1.0" iyz="0.0" izz="1.0"/>
    </inertial>
    <visual>
      <origin rpy="0.0 0.0 0.0" xyz="0.0 0.0 0.1"/>
      <geometry>
        <box size="0.2 0.2 0.2"/>
      </geometry>
      <material name="Blue">
        <color rgba="0.0 0.0 1.0 1.0"/>
      </material>
    </visual>
    <collision>
      <origin rpy="0.0 0.0 0.0" xyz="0.0 0.0 0.1"/>
      <geometry>
        <box size="0.2 0.2 0.2"/>
      </geometry>
    </collision>
  </link>
  <gazebo reference="a5_head">
    <selfCollide>true</selfCollide>
    <material>Gazebo/Blue</material>
  </gazebo>
  <!-- Joint -->
  <joint name="a5_joint" type="revolute">
    <origin rpy="0.0 0.0 0.0" xyz="0.0 0.0 0.5"/>
    <parent link="a5_tail"/>
    <child link="a5_head"/>
    <axis xyz="0.0 0.0 1.0"/>
    <limit effort="1000000" lower="-1.5707963267948966" upper="1.5707963267948966" velocity="1000000"/>
  </joint>
  <!-- Tail Link -->
  <link name="a6_tail">
    <inertial>
      <origin rpy="0.0 0.0 0.0" xyz="0.0 0.0 0.25"/>
      <mass value="1.0"/>
      <inertia ixx="1.0" ixy="0.0" ixz="0.0" iyy="1.0" iyz="0.0" izz="1.0"/>
    </inertial>
    <visual>
      <origin rpy="0.0 0.0 0.0" xyz="0.0 0.0 0.25"/>
      <geometry>
        <cylinder length="0.5" radius="0.1"/>
      </geometry>
      <material name="White">
        <color rgba="1.0 1.0 1.0 1.0"/>
      </material>
    </visual>
    <collision>
      <origin rpy="0.0 0.0 0.0" xyz="0.0 0.0 0.25"/>
      <geometry>
        <cylinder length="0.5" radius="0.1"/>
      </geometry>
    </collision>
  </link>
  <gazebo reference="a6_tail">
    <selfCollide>true</selfCollide>
    <material>Gazebo/White</material>
  </gazebo>
  <!-- Head Link -->
  <link name="a6_head">
    <inertial>
      <origin rpy="0.0 0.0 0.0" xyz="0.0 0.0 0.0"/>
      <mass value="1.0"/>
      <inertia ixx="1.0" ixy="0.0" ixz="0.0" iyy="1.0" iyz="0.0" izz="1.0"/>
    </inertial>
    <visual>
      <origin rpy="0.0 0.0 0.0" xyz="0.0 0.0 0.1"/>
      <geometry>
        <box size="0.2 0.2 0.2"/>
      </geometry>
      <material name="Blue">
        <color rgba="0.0 0.0 1.0 1.0"/>
      </material>
    </visual>
    <collision>
      <origin rpy="0.0 0.0 0.0" xyz="0.0 0.0 0.1"/>
      <geometry>
        <box size="0.2 0.2 0.2"/>
      </geometry>
    </collision>
  </link>
  <gazebo reference="a6_head">
    <selfCollide>true</selfCollide>
    <material>Gazebo/Blue</material>
  </gazebo>
  <!-- Joint -->
  <joint name="a6_joint" type="revolute">
    <origin rpy="0.0 0.0 0.0" xyz="0.0 0.0 0.5"/>
    <parent link="a6_tail"/>
    <child link="a6_head"/>
    <axis xyz="0.0 0.0 1.0"/>
    <limit effort="1000000" lower="-1.5707963267948966" upper="1.5707963267948966" velocity="1000000"/>
  </joint>
  <!-- Tail Link -->
  <link name="a7_tail">
    <inertial>
      <origin rpy="0.0 0.0 0.0" xyz="0.0 0.0 0.25"/>
      <mass value="1.0"/>
      <inertia ixx="1.0" ixy="0.0" ixz="0.0" iyy="1.0" iyz="0.0" izz="1.0"/>
    </inertial>
    <visual>
      <origin rpy="0.0 0.0 0.0" xyz="0.0 0.0 0.25"/>
      <geometry>
        <cylinder length="0.5" radius="0.1"/>
      </geometry>
      <material name="White">
        <color rgba="1.0 1.0 1.0 1.0"/>
      </material>
    </visual>
    <collision>
      <origin rpy="0.0 0.0 0.0" xyz="0.0 0.0 0.25"/>
      <geometry>
        <cylinder length="0.5" radius="0.1"/>
      </geometry>
    </collision>
  </link>
  <gazebo reference="a7_tail">
    <selfCollide>true</selfCollide>
    <material>Gazebo/White</material>
  </gazebo>
  <!-- Head Link -->
  <link name="a7_head">
    <inertial>
      <origin rpy="0.0 0.0 0.0" xyz="0.0 0.0 0.0"/>
      <mass value="1.0"/>
      <inertia ixx="1.0" ixy="0.0" ixz="0.0" iyy="1.0" iyz="0.0" izz="1.0"/>
    </inertial>
    <visual>
      <origin rpy="0.0 0.0 0.0" xyz="0.0 0.0 0.1"/>
      <geometry>
        <box size="0.2 0.2 0.2"/>
      </geometry>
      <material name="Blue">
        <color rgba="0.0 0.0 1.0 1.0"/>
      </material>
    </visual>
    <collision>
      <origin rpy="0.0 0.0 0.0" xyz="0.0 0.0 0.1"/>
      <geometry>
        <box size="0.2 0.2 0.2"/>
      </geometry>
    </collision>
  </link>
  <gazebo reference="a7_head">
    <selfCollide>true</selfCollide>
    <material>Gazebo/Blue</material>
  </gazebo>
  <!-- Joint -->
  <joint name="a7_joint" type="revolute">
    <origin rpy="0.0 0.0 0.0" xyz="0.0 0.0 0.5"/>
    <parent link="a7_tail"/>
    <child link="a7_head"/>
    <axis xyz="0.0 0.0 1.0"/>
    <limit effort="1000000" lower="-1.5707963267948966" upper="1.5707963267948966" velocity="1000000"/>
  </joint>
  <link name="world"/>
  <gazebo reference="world">
    <static>true</static>
  </gazebo>
  <joint name="pin" type="fixed">
    <parent link="world"/>
    <child link="a1_tail"/>
  </joint>
  <joint name="a1_a2_joint" type="fixed">
    <origin rpy="-1.5707963267948966 0.0 0" xyz="0.0 0.1 0.1"/>
    <parent link="a1_head"/>
    <child link="a2_tail"/>
  </joint>
  <joint name="a2_a3_joint" type="fixed">
    <origin rpy="0.0 -1.5707963267948966 0" xyz="-0.1 0.0 0.1"/>
    <parent link="a2_head"/>
    <child link="a3_tail"/>
  </joint>
  <joint name="a3_a4_joint" type="fixed">
    <origin rpy="1.5707963267948966 0.0 0" xyz="0.0 -0.1 0.1"/>
    <parent link="a3_head"/>
    <child link="a4_tail"/>
  </joint>
  <joint name="a4_a5_joint" type="fixed">
    <origin rpy="0.0 -1.5707963267948966 0" xyz="-0.1 0.0 0.1"/>
    <parent link="a4_head"/>
    <child link="a5_tail"/>
  </joint>
  <joint name="a5_a6_joint" type="fixed">
    <origin rpy="1.5707963267948966 0.0 0" xyz="0.0 -0.1 0.1"/>
    <parent link="a5_head"/>
    <child link="a6_tail"/>
  </joint>
  <joint name="a6_a7_joint" type="fixed">
    <origin rpy="0.0 1.5707963267948966 0" xyz="0.1 0.0 0.1"/>
    <parent link="a6_head"/>
    <child link="a7_tail"/>
  </joint>
</robot>
