<?xml version="1.0" ?>
<!-- =================================================================================== -->
<!-- |    This document was autogenerated by xacro from unibot.xacro                   | -->
<!-- |    EDITING THIS FILE BY HAND IS NOT RECOMMENDED                                 | -->
<!-- =================================================================================== -->
<robot name="unibot">
  <ros2_control name="GazeboSystem" type="system">
    <hardware>
      <plugin>gazebo_ros2_control/GazeboSystem</plugin>
    </hardware>
    <joint name="a1_joint">
      <command_interface name="effort">
        <param name="min">-100000</param>
        <param name="max">100000</param>
      </command_interface>
      <state_interface name="position"/>
      <state_interface name="velocity"/>
      <state_interface name="effort"/>
    </joint>
  </ros2_control>
  <gazebo>
    <plugin filename="libgazebo_ros2_control.so" name="gazebo_ros2_control">
      <parameters>/home/malebolge/ws/ros2_tutorials/install/ros2_control_tutorial/share/ros2_control_tutorial/config/controllers.yaml</parameters>
    </plugin>
  </gazebo>
  <!-- Tail Link -->
  <link name="a1_tail">
    <inertial>
      <origin rpy="0.0 0.0 0.0" xyz="0.0 0.0 0.25"/>
      <mass value="1.0"/>
      <inertia ixx="1.0" ixy="0.0" ixz="0.0" iyy="1.0" iyz="0.0" izz="1.0"/>
    </inertial>
    <visual>
      <origin rpy="0.0 0.0 0.0" xyz="0.0 0.0 0.25"/>
      <geometry>
        <cylinder length="0.5" radius="0.1"/>
      </geometry>
      <material name="White">
        <color rgba="1.0 1.0 1.0 1.0"/>
      </material>
    </visual>
    <collision>
      <origin rpy="0.0 0.0 0.0" xyz="0.0 0.0 0.25"/>
      <geometry>
        <cylinder length="0.5" radius="0.1"/>
      </geometry>
    </collision>
  </link>
  <gazebo reference="a1_tail">
    <selfCollide>true</selfCollide>
    <material>Gazebo/White</material>
  </gazebo>
  <!-- Head Link -->
  <link name="a1_head">
    <inertial>
      <origin rpy="0.0 0.0 0.0" xyz="0.0 0.0 0.0"/>
      <mass value="1.0"/>
      <inertia ixx="1.0" ixy="0.0" ixz="0.0" iyy="1.0" iyz="0.0" izz="1.0"/>
    </inertial>
    <visual>
      <origin rpy="0.0 0.0 0.0" xyz="0.0 0.0 0.1"/>
      <geometry>
        <box size="0.2 0.2 0.2"/>
      </geometry>
      <material name="Blue">
        <color rgba="0.0 0.0 1.0 1.0"/>
      </material>
    </visual>
    <collision>
      <origin rpy="0.0 0.0 0.0" xyz="0.0 0.0 0.1"/>
      <geometry>
        <box size="0.2 0.2 0.2"/>
      </geometry>
    </collision>
  </link>
  <gazebo reference="a1_head">
    <selfCollide>true</selfCollide>
    <material>Gazebo/Blue</material>
  </gazebo>
  <!-- Joint -->
  <joint name="a1_joint" type="continuous">
    <origin rpy="0.0 0.0 0.0" xyz="0.0 0.0 0.5"/>
    <parent link="a1_tail"/>
    <child link="a1_head"/>
    <axis xyz="0.0 0.0 1.0"/>
    <limit effort="1000000" lower="-6.283185307179586" upper="6.283185307179586" velocity="1000000"/>
  </joint>
  <!-- Tail Link -->
  <link name="a2_tail">
    <inertial>
      <origin rpy="0.0 0.0 0.0" xyz="0.0 0.0 0.25"/>
      <mass value="1.0"/>
      <inertia ixx="1.0" ixy="0.0" ixz="0.0" iyy="1.0" iyz="0.0" izz="1.0"/>
    </inertial>
    <visual>
      <origin rpy="0.0 0.0 0.0" xyz="0.0 0.0 0.25"/>
      <geometry>
        <cylinder length="0.5" radius="0.1"/>
      </geometry>
      <material name="White">
        <color rgba="1.0 1.0 1.0 1.0"/>
      </material>
    </visual>
    <collision>
      <origin rpy="0.0 0.0 0.0" xyz="0.0 0.0 0.25"/>
      <geometry>
        <cylinder length="0.5" radius="0.1"/>
      </geometry>
    </collision>
  </link>
  <gazebo reference="a2_tail">
    <selfCollide>true</selfCollide>
    <material>Gazebo/White</material>
  </gazebo>
  <!-- Head Link -->
  <link name="a2_head">
    <inertial>
      <origin rpy="0.0 0.0 0.0" xyz="0.0 0.0 0.0"/>
      <mass value="1.0"/>
      <inertia ixx="1.0" ixy="0.0" ixz="0.0" iyy="1.0" iyz="0.0" izz="1.0"/>
    </inertial>
    <visual>
      <origin rpy="0.0 0.0 0.0" xyz="0.0 0.0 0.1"/>
      <geometry>
        <box size="0.2 0.2 0.2"/>
      </geometry>
      <material name="Blue">
        <color rgba="0.0 0.0 1.0 1.0"/>
      </material>
    </visual>
    <collision>
      <origin rpy="0.0 0.0 0.0" xyz="0.0 0.0 0.1"/>
      <geometry>
        <box size="0.2 0.2 0.2"/>
      </geometry>
    </collision>
  </link>
  <gazebo reference="a2_head">
    <selfCollide>true</selfCollide>
    <material>Gazebo/Blue</material>
  </gazebo>
  <!-- Joint -->
  <joint name="a2_joint" type="continuous">
    <origin rpy="0.0 0.0 0.0" xyz="0.0 0.0 0.5"/>
    <parent link="a2_tail"/>
    <child link="a2_head"/>
    <axis xyz="0.0 0.0 1.0"/>
    <limit effort="1000000" lower="-6.283185307179586" upper="6.283185307179586" velocity="1000000"/>
  </joint>
  <link name="world"/>
  <gazebo reference="world">
    <static>true</static>
  </gazebo>
  <joint name="pin" type="fixed">
    <parent link="world"/>
    <child link="a1_tail"/>
  </joint>
  <joint name="a1_a2_joint" type="fixed">
    <origin rpy="-1.5707963267948966 0.0 0" xyz="0.0 0.1 0.1"/>
    <parent link="a1_head"/>
    <child link="a2_tail"/>
  </joint>
</robot>
